<?xml version="1.0" ?>
<!-- =================================================================================== -->
<!-- |    This document was autogenerated by xacro from /home/litao/catkin_ws/src/rokae_with_ins_platform/rokae_with_ins_description/urdf/realsense_rokae_platform.urdf.xacro | -->
<!-- |    EDITING THIS FILE BY HAND IS NOT RECOMMENDED                                 | -->
<!-- =================================================================================== -->
<robot name="realsense_rokae_platform">
    <!-- Constants for robot dimensions -->
    <material name="black">
        <color rgba="0.0 0.0 0.0 1.0" />
    </material>
    <material name="blue">
        <color rgba="0.0 0.0 0.8 1.0" />
    </material>
    <material name="green">
        <color rgba="0.0 0.8 0.0 1.0" />
    </material>
    <material name="grey">
        <color rgba="0.2 0.2 0.2 1.0" />
    </material>
    <material name="orange">
        <color rgba="1.0 0.4235294117647059 0.0392156862745098 1.0" />
    </material>
    <material name="brown">
        <color rgba="0.8705882352941177 0.8117647058823529 0.7647058823529411 1.0" />
    </material>
    <material name="red">
        <color rgba="0.8 0.0 0.0 1.0" />
    </material>
    <material name="white">
        <color rgba="1.0 1.0 1.0 1.0" />
    </material>
    <material name="Beige">
        <color rgba="1.0 0.784 0.5765 1.0" />
    </material>
    <!--base-->
    <link name="xMateCR7_base">
        <visual>
            <geometry>
                <mesh filename="package://rokae_description/meshes/xMateCR7/visual/xMateCR7_base.stl" scale="0.001 0.001 0.001" />
            </geometry>
            <origin rpy="0 0 0" xyz="0.0 0.0 0.0" />
            <material name="white" />
        </visual>
        <inertial>
            <mass value="3.44074938" />
            <inertia ixx="0.01764837" ixy="0" ixz="0" iyy="0.016617391" iyz="-0.002218013" izz="1.120163944" />
            <origin rpy="0 0 0" xyz="-0.000072769597 -0.01679187012 0.2986854502" />
        </inertial>
        <collision>
            <geometry>
                <mesh filename="package://rokae_description/meshes/xMateCR7/collision/xMateCR7_base.stl" scale="0.001 0.001 0.001" />
            </geometry>
            <origin rpy="0 0 0" xyz="0.0 0.0 0.0" />
        </collision>
    </link>
    <joint name="joint1" type="revolute">
        <parent link="xMateCR7_base" />
        <child link="xMateCR7_link1" />
        <limit effort="300" lower="-3.1416" upper="3.1416" velocity="10" />
        <axis xyz="0 0 1" />
        <origin rpy="0 0 0" xyz="0 0 0" />
    </joint>
    <transmission name="tran1">
        <type>transmission_interface/SimpleTransmission</type>
        <joint name="joint1">
            <hardwareInterface>hardware_interface/EffortJointInterface</hardwareInterface>
        </joint>
        <actuator name="motor1">
            <hardwareInterface>hardware_interface/EffortJointInterface</hardwareInterface>
            <mechanicalReduction>1</mechanicalReduction>
        </actuator>
    </transmission>
    <!--link 1-->
    <link name="xMateCR7_link1">
        <visual>
            <geometry>
                <mesh filename="package://rokae_description/meshes/xMateCR7/visual/xMateCR7_link1.stl" scale="0.001 0.001 0.001" />
            </geometry>
            <origin rpy="0 0 0" xyz="0 0 0" />
            <material name="white" />
        </visual>
        <inertial>
            <mass value="3.44074938" />
            <inertia ixx="0.01764837" ixy="0" ixz="0" iyy="0.016617391" iyz="-0.002218013" izz="1.120163944" />
            <origin rpy="0 0 0" xyz="-0.000072769597 -0.01679187012 0.2986854502" />
        </inertial>
        <collision>
            <geometry>
                <mesh filename="package://rokae_description/meshes/xMateCR7/collision/xMateCR7_link1.stl" scale="0.001 0.001 0.001" />
            </geometry>
            <origin rpy="0 0 0" xyz="0 0 0" />
        </collision>
    </link>
    <joint name="joint2" type="revolute">
        <parent link="xMateCR7_link1" />
        <child link="xMateCR7_link2" />
        <limit effort="300" lower="-3.1416" upper="3.1416" velocity="10" />
        <axis xyz="0 1 0" />
        <origin rpy="0 0 0" xyz="0 0 0.296" />
    </joint>
    <transmission name="tran2">
        <type>transmission_interface/SimpleTransmission</type>
        <joint name="joint2">
            <hardwareInterface>hardware_interface/EffortJointInterface</hardwareInterface>
        </joint>
        <actuator name="motor2">
            <hardwareInterface>hardware_interface/EffortJointInterface</hardwareInterface>
            <mechanicalReduction>1</mechanicalReduction>
        </actuator>
    </transmission>
    <!--link 2-->
    <link name="xMateCR7_link2">
        <visual>
            <geometry>
                <mesh filename="package://rokae_description/meshes/xMateCR7/visual/xMateCR7_link2.stl" scale="0.001 0.001 0.001" />
            </geometry>
            <origin rpy="0 0 0" xyz="0 0 0.0" />
            <material name="white" />
        </visual>
        <inertial>
            <mass value="5.024380503" />
            <inertia ixx="0.136759927" ixy="0" ixz="0" iyy="1.747453457" iyz="-0.024189444" izz="0.012535321" />
            <origin rpy="0 0 0" xyz="-0 0.003491209523 0.2410487354" />
        </inertial>
        <collision>
            <geometry>
                <mesh filename="package://rokae_description/meshes/xMateCR7/collision/xMateCR7_link2.stl" scale="0.001 0.001 0.001" />
            </geometry>
            <origin rpy="0 0 0" xyz="0 0 0.0" />
        </collision>
    </link>
    <joint name="joint3" type="revolute">
        <parent link="xMateCR7_link2" />
        <child link="xMateCR7_link3" />
        <limit effort="300" lower="-3.1416" upper="3.1416" velocity="10" />
        <axis xyz="0 -1 0" />
        <origin rpy="0 0 0" xyz="0 0 0.49" />
    </joint>
    <transmission name="tran3">
        <type>transmission_interface/SimpleTransmission</type>
        <joint name="joint3">
            <hardwareInterface>hardware_interface/EffortJointInterface</hardwareInterface>
        </joint>
        <actuator name="motor3">
            <hardwareInterface>hardware_interface/EffortJointInterface</hardwareInterface>
            <mechanicalReduction>1</mechanicalReduction>
        </actuator>
    </transmission>
    <!--${nameofManipulator}_link 3-->
    <link name="xMateCR7_link3">
        <visual>
            <geometry>
                <mesh filename="package://rokae_description/meshes/xMateCR7/visual/xMateCR7_link3.stl" scale="0.001 0.001 0.001" />
            </geometry>
            <origin rpy="0 0 0" xyz="0 0 0" />
            <material name="white" />
        </visual>
        <inertial>
            <mass value="2.439584706" />
            <inertia ixx="0.026159338" ixy="0" ixz="0" iyy="0.024282179" iyz="-0.00615637" izz="1.11989835" />
            <origin rpy="0 0 0" xyz="0 0.023 0.097" />
        </inertial>
        <collision>
            <geometry>
                <mesh filename="package://rokae_description/meshes/xMateCR7/collision/xMateCR7_link3.stl" scale="0.001 0.001 0.001" />
            </geometry>
            <origin rpy="0 0 0" xyz="0 0 0" />
        </collision>
    </link>
    <joint name="joint4" type="revolute">
        <parent link="xMateCR7_link3" />
        <child link="xMateCR7_link4" />
        <limit effort="300" lower="-3.1416" upper="3.1416" velocity="10" />
        <!--     lower="-2.79" upper="2.79" -->
        <axis xyz="0 0 1" />
        <!--     <origin rpy="0 0 0" xyz="0.585 0.0 0.035"/> -->
        <origin rpy="0 0 0" xyz="0 0 0.36" />
    </joint>
    <transmission name="tran4">
        <type>transmission_interface/SimpleTransmission</type>
        <joint name="joint4">
            <hardwareInterface>hardware_interface/EffortJointInterface</hardwareInterface>
        </joint>
        <actuator name="motor4">
            <hardwareInterface>hardware_interface/EffortJointInterface</hardwareInterface>
            <mechanicalReduction>1</mechanicalReduction>
        </actuator>
    </transmission>
    <!--link 4-->
    <link name="xMateCR7_link4">
        <visual>
            <geometry>
                <mesh filename="package://rokae_description/meshes/xMateCR7/visual/xMateCR7_link4.stl" scale=".001 0.001 0.001" />
            </geometry>
            <origin rpy="0 0 0" xyz="0.0 0.0 0.0" />
            <material name="white" />
        </visual>
        <inertial>
            <mass value="2.439584706" />
            <inertia ixx="0.012" ixy="0" ixz="0" iyy="0.221" iyz="-0.002" izz="0.004" />
            <origin rpy="0 0 0" xyz="0 -0.020 -0.046" />
        </inertial>
        <collision>
            <geometry>
                <mesh filename="package://rokae_description/meshes/xMateCR7/collision/xMateCR7_link4.stl" scale="0.001 0.001 0.001" />
            </geometry>
            <origin rpy="0 0 0" xyz="0.0 0.0 0.0" />
        </collision>
    </link>
    <joint name="joint5" type="revolute">
        <parent link="xMateCR7_link4" />
        <child link="xMateCR7_link5" />
        <limit effort="300" lower="-3.1416" upper="3.1416" velocity="10" />
        <axis xyz="0 -1 0" />
        <origin rpy="0 0 0" xyz="0 -0.151 0" />
    </joint>
    <transmission name="tran5">
        <type>transmission_interface/SimpleTransmission</type>
        <joint name="joint5">
            <hardwareInterface>hardware_interface/EffortJointInterface</hardwareInterface>
        </joint>
        <actuator name="motor5">
            <hardwareInterface>hardware_interface/EffortJointInterface</hardwareInterface>
            <mechanicalReduction>1</mechanicalReduction>
        </actuator>
    </transmission>
    <!--link 5-->
    <link name="xMateCR7_link5">
        <visual>
            <geometry>
                <mesh filename="package://rokae_description/meshes/xMateCR7/visual/xMateCR7_link5.stl" scale="0.001 0.001 0.001" />
            </geometry>
            <origin rpy="0 0 0" xyz="0 0 0" />
            <material name="white" />
        </visual>
        <inertial>
            <mass value="2.422757896" />
            <inertia ixx="0.016" ixy="0" ixz="0" iyy="0.015" iyz="-0.002" izz="0.213" />
            <origin rpy="0 0 0" xyz="0 0.012 0.096" />
        </inertial>
        <collision>
            <geometry>
                <mesh filename="package://rokae_description/meshes/xMateCR7/collision/xMateCR7_link5.stl" scale="0.001 0.001 0.001" />
            </geometry>
            <origin rpy="0 0 0" xyz="0 0 0" />
        </collision>
    </link>
    <joint name="joint6" type="revolute">
        <parent link="xMateCR7_link5" />
        <child link="xMateCR7_link6" />
        <limit effort="300" lower="-3.1416" upper="3.1416" velocity="10" />
        <axis xyz="0 0 1" />
        <origin rpy="0.0 0.0 0" xyz="0 0 0.1265" />
    </joint>
    <transmission name="tran6">
        <type>transmission_interface/SimpleTransmission</type>
        <joint name="joint6">
            <hardwareInterface>hardware_interface/EffortJointInterface</hardwareInterface>
        </joint>
        <actuator name="motor6">
            <hardwareInterface>hardware_interface/EffortJointInterface</hardwareInterface>
            <mechanicalReduction>1</mechanicalReduction>
        </actuator>
    </transmission>
    <!--link 6-->
    <link name="xMateCR7_link6">
        <visual>
            <geometry>
                <mesh filename="package://rokae_description/meshes/xMateCR7/visual/xMateCR7_link6.stl" scale="0.001 0.001 0.001" />
            </geometry>
            <origin rpy="0 0 0" xyz="0.0 0.0 0.0" />
            <material name="white" />
        </visual>
        <inertial>
            <mass value="1.229800857" />
            <inertia ixx="0.002" ixy="-0.000000" ixz="-0.000000" iyy="0.212" iyz="-0.000000" izz="0.002" />
            <origin rpy="0 0 0" xyz="0 0.017 -0.043" />
        </inertial>
        <collision>
            <geometry>
                <mesh filename="package://rokae_description/meshes/xMateCR7/collision/xMateCR7_link6.stl" scale="0.001 0.001 0.001" />
            </geometry>
            <origin rpy="0 0 0" xyz="0.0 0.0 0.0" />
        </collision>
    </link>
    <link name="ft_sensor">
        <visual>
            <origin rpy="0 0 0" xyz="0 -0.0 0" />
            <geometry>
                <mesh filename="package://ft_sensor/meshes/ft_sensor.STL" scale="0.001 0.001 0.001" />
            </geometry>
        </visual>
        <collision>
            <geometry>
                <mesh filename="package://ft_sensor/meshes/ft_sensor.STL" scale="0.001 0.001 0.001" />
            </geometry>
            <origin rpy="0.0 0.0 0.0" xyz="0.0 0 0.0" />
        </collision>
        <inertial>
            <mass value="0.235" />
            <inertia ixx="7.1441E-05" ixy="1.6499E-08" ixz="-4.9269E-09" iyy="7.146E-05" iyz="-8.5336E-09" izz="0.00013366" />
            <origin xyz="0 0 0" rpy="0 0 0" />
        </inertial>
    </link>
    <joint name="ft_sensor_joint" type="fixed">
        <origin rpy="0.0 0.0 0.0" xyz="-0.03 -0.03 0.0" />
        <parent link="xMateCR7_link6" />
        <child link="ft_sensor" />
        <axis xyz="0.0 0.0 0.0" />
        <limit effort="0.0" lower="0.0" upper="0.0" velocity="0.0" />
    </joint>
    <!-- Enable the Joint Feedback -->
    <gazebo reference="ft_sensor_joint">
        <provideFeedback>true</provideFeedback>
        <disableFixedJointLumping>true</disableFixedJointLumping>
        <plugin name="gazebo_ros_control">
            <robotNamespace>/</robotNamespace>
        </plugin>
    </gazebo>
    <!-- The ft_sensor plugin -->
    <gazebo>
        <plugin filename="libgazebo_ros_ft_sensor.so" name="ft_sensor">
            <updateRate>100.0</updateRate>
            <topicName>ft_sensor_topic</topicName>
            <jointName>ft_sensor_joint</jointName>
        </plugin>
    </gazebo>
    <link name="dummy" />
    <joint name="dummy_joint" type="fixed">
        <parent link="dummy" />
        <child link="Base_Link" />
    </joint>
    <link name="Base_Link">
        <inertial>
            <origin rpy="0 0 0" xyz="0.0284046972660885 -0.00981060404810299 0.0222000386975785" />
            <mass value="0.22621959250221" />
            <inertia ixx="0.000161057742168925" ixy="-3.93039257205975E-06" ixz="-2.59552833985103E-06" iyy="0.000358621491446785" iyz="4.70540238948447E-06" izz="0.000257940666810454" />
        </inertial>
        <visual>
            <origin rpy="0 0 0" xyz="0 0 0" />
            <geometry>
                <mesh filename="package://inspire_hand_description/meshes/Base_Link.STL" />
            </geometry>
            <material name="">
                <color rgba="0.827450980392157 0.83921568627451 0.827450980392157 1" />
            </material>
        </visual>
        <collision>
            <origin rpy="0 0 0" xyz="0 0 0" />
            <geometry>
                <mesh filename="package://inspire_hand_description/meshes/Base_Link.STL" />
            </geometry>
        </collision>
    </link>
    <link name="Link1">
        <inertial>
            <origin rpy="0 0 0" xyz="0.0107729817589723 0.00213781834563882 -1.34009238303423E-07" />
            <mass value="0.00330620599604871" />
            <inertia ixx="1.55837657646135E-07" ixy="-3.78958094877833E-08" ixz="-5.07264353075226E-12" iyy="5.30383928507338E-07" iyz="-1.43523102869642E-12" izz="5.55164105212297E-07" />
        </inertial>
        <visual>
            <origin rpy="0 0 0" xyz="0 0 0" />
            <geometry>
                <mesh filename="package://inspire_hand_description/meshes/Link1.STL" />
            </geometry>
            <material name="">
                <color rgba="0.792156862745098 0.819607843137255 0.933333333333333 1" />
            </material>
        </visual>
        <collision>
            <origin rpy="0 0 0" xyz="0 0 0" />
            <geometry>
                <mesh filename="package://inspire_hand_description/meshes/Link1.STL" />
            </geometry>
        </collision>
    </link>
    <joint name="Index_Finger_Joint1" type="revolute">
        <origin rpy="5.2178E-10 -6.245E-17 -0.14966" xyz="0.08225 -0.0077547 -0.0040172" />
        <parent link="Base_Link" />
        <child link="Link1" />
        <axis xyz="0 0 1" />
        <limit effort="1" lower="-1.6" upper="0" velocity="1" />
    </joint>
    <link name="Link11">
        <inertial>
            <origin rpy="0 0 0" xyz="0.019017916514892 0.00563447754295066 1.90796464460963E-08" />
            <mass value="0.00453366822308025" />
            <inertia ixx="8.56969764665792E-08" ixy="-3.65502775787085E-08" ixz="2.02841411241907E-12" iyy="7.58232170757561E-07" iyz="6.07603435089188E-13" izz="7.68830975890361E-07" />
        </inertial>
        <visual>
            <origin rpy="0 0 0" xyz="0 0 0" />
            <geometry>
                <mesh filename="package://inspire_hand_description/meshes/Link11.STL" />
            </geometry>
            <material name="">
                <color rgba="1 1 1 1" />
            </material>
        </visual>
        <collision>
            <origin rpy="0 0 0" xyz="0 0 0" />
            <geometry>
                <mesh filename="package://inspire_hand_description/meshes/Link11.STL" />
            </geometry>
        </collision>
    </link>
    <joint name="Index_Finger_Joint2" type="revolute">
        <origin rpy="-5.086E-10 -1.1653E-10 -0.22524" xyz="0.032132 0 0" />
        <parent link="Link1" />
        <child link="Link11" />
        <axis xyz="0 0 1" />
        <limit effort="1" lower="-1.7" upper="0" velocity="1" />
    </joint>
    <link name="Link2">
        <inertial>
            <origin rpy="0 0 0" xyz="0.0107729781873397 0.00213783567195037 -1.14076048385314E-07" />
            <mass value="0.00330621565435093" />
            <inertia ixx="1.55837752420093E-07" ixy="-3.78955767951184E-08" ixz="-4.51740252002264E-12" iyy="5.30384784494186E-07" iyz="-1.08751322448059E-12" izz="5.55164342998361E-07" />
        </inertial>
        <visual>
            <origin rpy="0 0 0" xyz="0 0 0" />
            <geometry>
                <mesh filename="package://inspire_hand_description/meshes/Link2.STL" />
            </geometry>
            <material name="">
                <color rgba="0.792156862745098 0.819607843137255 0.933333333333333 1" />
            </material>
        </visual>
        <collision>
            <origin rpy="0 0 0" xyz="0 0 0" />
            <geometry>
                <mesh filename="package://inspire_hand_description/meshes/Link2.STL" />
            </geometry>
        </collision>
    </link>
    <joint name="Middle_Finger_joint1" type="revolute">
        <origin rpy="0.0056158 -0.034452 -0.16161" xyz="0.081939 -0.0077547 0.015305" />
        <parent link="Base_Link" />
        <child link="Link2" />
        <axis xyz="0 0 1" />
        <limit effort="1" lower="-1.6" upper="0" velocity="1" />
    </joint>
    <link name="Link22">
        <inertial>
            <origin rpy="0 0 0" xyz="0.0190179451505274 0.00563447968575673 1.97663586783137E-08" />
            <mass value="0.00453367017295165" />
            <inertia ixx="8.5696963969299E-08" ixy="-3.6550923619766E-08" ixz="1.59786933213099E-12" iyy="7.58233066456215E-07" iyz="6.81108952684927E-13" izz="7.68832070821997E-07" />
        </inertial>
        <visual>
            <origin rpy="0 0 0" xyz="0 0 0" />
            <geometry>
                <mesh filename="package://inspire_hand_description/meshes/Link22.STL" />
            </geometry>
            <material name="">
                <color rgba="1 1 1 1" />
            </material>
        </visual>
        <collision>
            <origin rpy="0 0 0" xyz="0 0 0" />
            <geometry>
                <mesh filename="package://inspire_hand_description/meshes/Link22.STL" />
            </geometry>
        </collision>
    </link>
    <joint name="Middle_Finger_joint2" type="revolute">
        <origin rpy="-5.0853E-10 -1.1686E-10 -0.22588" xyz="0.032132 0 0" />
        <parent link="Link2" />
        <child link="Link22" />
        <axis xyz="0 0 1" />
        <limit effort="1" lower="-1.7" upper="0" velocity="1" />
    </joint>
    <link name="Link3">
        <inertial>
            <origin rpy="0 0 0" xyz="0.0107730930654459 0.00213783260244832 -8.57328914740003E-08" />
            <mass value="0.0033061482917439" />
            <inertia ixx="1.55835970052989E-07" ixy="-3.78956285985318E-08" ixz="-3.98553229256186E-12" iyy="5.30379079243718E-07" iyz="-6.32137439938121E-13" izz="5.5516012983777E-07" />
        </inertial>
        <visual>
            <origin rpy="0 0 0" xyz="0 0 0" />
            <geometry>
                <mesh filename="package://inspire_hand_description/meshes/Link3.STL" />
            </geometry>
            <material name="">
                <color rgba="0.792156862745098 0.819607843137255 0.933333333333333 1" />
            </material>
        </visual>
        <collision>
            <origin rpy="0 0 0" xyz="0 0 0" />
            <geometry>
                <mesh filename="package://inspire_hand_description/meshes/Link3.STL" />
            </geometry>
        </collision>
    </link>
    <joint name="Ring_Finger_Joint1" type="revolute">
        <origin rpy="0.010408 -0.086645 -0.11971" xyz="0.080765 -0.0077547 0.034505" />
        <parent link="Base_Link" />
        <child link="Link3" />
        <axis xyz="0 0 1" />
        <limit effort="1" lower="-1.6" upper="0" velocity="1" />
    </joint>
    <link name="Link33">
        <inertial>
            <origin rpy="0 0 0" xyz="0.01901789870244 0.00563447090562313 1.70050325960271E-08" />
            <mass value="0.00453366652527048" />
            <inertia ixx="8.56969335058099E-08" ixy="-3.65501984156752E-08" ixz="1.30339239962579E-12" iyy="7.58232117591424E-07" iyz="7.47249892192207E-13" izz="7.68830949295352E-07" />
        </inertial>
        <visual>
            <origin rpy="0 0 0" xyz="0 0 0" />
            <geometry>
                <mesh filename="package://inspire_hand_description/meshes/Link33.STL" />
            </geometry>
            <material name="">
                <color rgba="1 1 1 1" />
            </material>
        </visual>
        <collision>
            <origin rpy="0 0 0" xyz="0 0 0" />
            <geometry>
                <mesh filename="package://inspire_hand_description/meshes/Link33.STL" />
            </geometry>
        </collision>
    </link>
    <joint name="Ring_Finger_Joint2" type="revolute">
        <origin rpy="-5.0314E-10 -1.3824E-10 -0.26815" xyz="0.032132 0 0" />
        <parent link="Link3" />
        <child link="Link33" />
        <axis xyz="0 0 1" />
        <limit effort="1" lower="-1.7" upper="0" velocity="1" />
    </joint>
    <link name="Link4">
        <inertial>
            <origin rpy="0 0 0" xyz="0.0107729931213964 0.00213782731321216 -7.95186542376647E-08" />
            <mass value="0.00330620800050046" />
            <inertia ixx="1.55837389573248E-07" ixy="-3.78958987950181E-08" ixz="-3.73884747536307E-12" iyy="5.30384597648764E-07" iyz="-3.63224479792676E-13" izz="5.55163794949727E-07" />
        </inertial>
        <visual>
            <origin rpy="0 0 0" xyz="0 0 0" />
            <geometry>
                <mesh filename="package://inspire_hand_description/meshes/Link4.STL" />
            </geometry>
            <material name="">
                <color rgba="0.792156862745098 0.819607843137255 0.933333333333333 1" />
            </material>
        </visual>
        <collision>
            <origin rpy="0 0 0" xyz="0 0 0" />
            <geometry>
                <mesh filename="package://inspire_hand_description/meshes/Link4.STL" />
            </geometry>
        </collision>
    </link>
    <joint name="Little_Thump_Joint1" type="revolute">
        <origin rpy="0.022524 -0.13781 -0.16255" xyz="0.078587 -0.0077547 0.053617" />
        <parent link="Base_Link" />
        <child link="Link4" />
        <axis xyz="0 0 1" />
        <limit effort="1" lower="-1.6" upper="0" velocity="1" />
    </joint>
    <link name="Link44">
        <inertial>
            <origin rpy="0 0 0" xyz="0.0155924853997512 0.00555619186912998 -1.21775195708468E-07" />
            <mass value="0.00356886192445218" />
            <inertia ixx="6.67767175628229E-08" ixy="-2.70385196277176E-08" ixz="-4.60032318294332E-12" iyy="4.33416353432936E-07" iyz="-1.36538016248102E-12" izz="4.39760949009649E-07" />
        </inertial>
        <visual>
            <origin rpy="0 0 0" xyz="0 0 0" />
            <geometry>
                <mesh filename="package://inspire_hand_description/meshes/Link44.STL" />
            </geometry>
            <material name="">
                <color rgba="1 1 1 1" />
            </material>
        </visual>
        <collision>
            <origin rpy="0 0 0" xyz="0 0 0" />
            <geometry>
                <mesh filename="package://inspire_hand_description/meshes/Link44.STL" />
            </geometry>
        </collision>
    </link>
    <joint name="Little_Thump_Joint2" type="revolute">
        <origin rpy="-5.0686E-10 -1.2389E-10 -0.23972" xyz="0.032132 0 0" />
        <parent link="Link4" />
        <child link="Link44" />
        <axis xyz="0 0 1" />
        <limit effort="1" lower="-1.7" upper="0" velocity="1" />
    </joint>
    <link name="Link5">
        <inertial>
            <origin rpy="0 0 0" xyz="-0.000668287872925624 -0.00209320996353089 0.0037633441647693" />
            <mass value="0.00487390663164139" />
            <inertia ixx="1.30408513803687E-07" ixy="-8.92030281859617E-09" ixz="-1.7660325194859E-08" iyy="1.70578986810531E-07" iyz="-1.02749399337787E-09" izz="2.1170907785655E-07" />
        </inertial>
        <visual>
            <origin rpy="0 0 0" xyz="0 0 0" />
            <geometry>
                <mesh filename="package://inspire_hand_description/meshes/Link5.STL" />
            </geometry>
            <material name="">
                <color rgba="0.827450980392157 0.83921568627451 0.827450980392157 1" />
            </material>
        </visual>
        <collision>
            <origin rpy="0 0 0" xyz="0 0 0" />
            <geometry>
                <mesh filename="package://inspire_hand_description/meshes/Link5.STL" />
            </geometry>
        </collision>
    </link>
    <joint name="Big_Thump_Joint1" type="revolute">
        <origin rpy="0.092365 1.1827 -1.4853" xyz="0.0089225 -0.022949 -0.00699" />
        <parent link="Base_Link" />
        <child link="Link5" />
        <axis xyz="0 1 0" />
        <limit effort="1" lower="-1" upper="0.3" velocity="1" />
    </joint>
    <link name="Link51">
        <inertial>
            <origin rpy="0 0 0" xyz="0.0261732090129406 0.00353701767650547 -1.92601341111875E-07" />
            <mass value="0.00652729219675812" />
            <inertia ixx="8.93817123585481E-07" ixy="6.28368840765271E-08" ixz="-2.00458419649248E-11" iyy="2.37370603240555E-06" iyz="-1.67466441559282E-12" izz="2.75021956933668E-06" />
        </inertial>
        <visual>
            <origin rpy="0 0 0" xyz="0 0 0" />
            <geometry>
                <mesh filename="package://inspire_hand_description/meshes/Link51.STL" />
            </geometry>
            <material name="">
                <color rgba="0.792156862745098 0.819607843137255 0.933333333333333 1" />
            </material>
        </visual>
        <collision>
            <origin rpy="0 0 0" xyz="0 0 0" />
            <geometry>
                <mesh filename="package://inspire_hand_description/meshes/Link51.STL" />
            </geometry>
        </collision>
    </link>
    <joint name="Big_Thump_Joint2" type="revolute">
        <origin rpy="3.1416 -5.2736E-16 0.96726" xyz="0.0065 -0.0035 0.00425" />
        <parent link="Link5" />
        <child link="Link51" />
        <axis xyz="0 0 -1" />
        <limit effort="1" lower="0" upper="0.4" velocity="1" />
    </joint>
    <link name="Link52">
        <inertial>
            <origin rpy="0 0 0" xyz="-0.007316119869056 -0.00552223433089214 2.14610152510231E-07" />
            <mass value="0.0022695308360543" />
            <inertia ixx="1.7281059843115E-07" ixy="4.52282139518593E-08" ixz="-2.88816078436063E-12" iyy="2.78046552011382E-07" iyz="7.05843881266438E-13" izz="2.99630657437474E-07" />
        </inertial>
        <visual>
            <origin rpy="0 0 0" xyz="0 0 0" />
            <geometry>
                <mesh filename="package://inspire_hand_description/meshes/Link52.STL" />
            </geometry>
            <material name="">
                <color rgba="0.827450980392157 0.83921568627451 0.827450980392157 1" />
            </material>
        </visual>
        <collision>
            <origin rpy="0 0 0" xyz="0 0 0" />
            <geometry>
                <mesh filename="package://inspire_hand_description/meshes/Link52.STL" />
            </geometry>
        </collision>
    </link>
    <joint name="Big_Thump_Joint3" type="revolute">
        <origin rpy="0 -1.3878E-16 2.9661" xyz="0.056001 0 0" />
        <parent link="Link51" />
        <child link="Link52" />
        <axis xyz="0 0 1" />
        <limit effort="1" lower="-0.4" upper="0" velocity="1" />
    </joint>
    <link name="Link53">
        <inertial>
            <origin rpy="0 0 0" xyz="-3.3937612879259E-06 0.0106230303829815 0.000584861433263272" />
            <mass value="0.00330869751403717" />
            <inertia ixx="1.96169236089202E-07" ixy="-1.43223823727531E-10" ixz="5.64113109591019E-11" iyy="8.67914197835909E-08" iyz="2.46315104630635E-08" izz="1.85481756939709E-07" />
        </inertial>
        <visual>
            <origin rpy="0 0 0" xyz="0 0 0" />
            <geometry>
                <mesh filename="package://inspire_hand_description/meshes/Link53.STL" />
            </geometry>
            <material name="">
                <color rgba="0.827450980392157 0.83921568627451 0.827450980392157 1" />
            </material>
        </visual>
        <collision>
            <origin rpy="0 0 0" xyz="0 0 0" />
            <geometry>
                <mesh filename="package://inspire_hand_description/meshes/Link53.STL" />
            </geometry>
        </collision>
    </link>
    <joint name="Big_Thump_Joint4" type="revolute">
        <origin rpy="1.7291 -1.5708 0" xyz="-0.022653 0 0" />
        <parent link="Link52" />
        <child link="Link53" />
        <axis xyz="1 0 0" />
        <limit effort="1" lower="-1" upper="0" velocity="1" />
    </joint>
    <transmission name="Little_Thump_Joint1_trans">
        <type>transmission_interface/SimpleTransmission</type>
        <joint name="Little_Thump_Joint1">
            <hardwareInterface>hardware_interface/PositionJointInterface</hardwareInterface>
        </joint>
        <actuator name="Little_Thump_Joint1_motor">
            <mechanicalReduction>1</mechanicalReduction>
            <hardwareInterface>hardware_interface/PositionJointInterface</hardwareInterface>
        </actuator>
    </transmission>
    <transmission name="Little_Thump_Joint2_trans">
        <type>transmission_interface/SimpleTransmission</type>
        <joint name="Little_Thump_Joint2">
            <hardwareInterface>hardware_interface/PositionJointInterface</hardwareInterface>
        </joint>
        <actuator name="Little_Thump_Joint2_motor">
            <mechanicalReduction>1</mechanicalReduction>
            <hardwareInterface>hardware_interface/PositionJointInterface</hardwareInterface>
        </actuator>
    </transmission>
    <transmission name="Ring_Finger_Joint1_trans">
        <type>transmission_interface/SimpleTransmission</type>
        <joint name="Ring_Finger_Joint1">
            <hardwareInterface>hardware_interface/PositionJointInterface</hardwareInterface>
        </joint>
        <actuator name="Ring_Finger_Joint1_motor">
            <mechanicalReduction>1</mechanicalReduction>
            <hardwareInterface>hardware_interface/PositionJointInterface</hardwareInterface>
        </actuator>
    </transmission>
    <transmission name="Ring_Finger_Joint2_trans">
        <type>transmission_interface/SimpleTransmission</type>
        <joint name="Ring_Finger_Joint2">
            <hardwareInterface>hardware_interface/PositionJointInterface</hardwareInterface>
        </joint>
        <actuator name="Ring_Finger_Joint2_motor">
            <mechanicalReduction>1</mechanicalReduction>
            <hardwareInterface>hardware_interface/PositionJointInterface</hardwareInterface>
        </actuator>
    </transmission>
    <transmission name="Middle_Finger_joint1_trans">
        <type>transmission_interface/SimpleTransmission</type>
        <joint name="Middle_Finger_joint1">
            <hardwareInterface>hardware_interface/PositionJointInterface</hardwareInterface>
        </joint>
        <actuator name="Middle_Finger_joint1_motor">
            <mechanicalReduction>1</mechanicalReduction>
            <hardwareInterface>hardware_interface/PositionJointInterface</hardwareInterface>
        </actuator>
    </transmission>
    <transmission name="Middle_Finger_joint2_trans">
        <type>transmission_interface/SimpleTransmission</type>
        <joint name="Middle_Finger_joint2">
            <hardwareInterface>hardware_interface/PositionJointInterface</hardwareInterface>
        </joint>
        <actuator name="Middle_Finger_joint2_motor">
            <mechanicalReduction>1</mechanicalReduction>
            <hardwareInterface>hardware_interface/PositionJointInterface</hardwareInterface>
        </actuator>
    </transmission>
    <transmission name="Index_Finger_Joint1_trans">
        <type>transmission_interface/SimpleTransmission</type>
        <joint name="Index_Finger_Joint1">
            <hardwareInterface>hardware_interface/PositionJointInterface</hardwareInterface>
        </joint>
        <actuator name="Index_Finger_Joint1_motor">
            <mechanicalReduction>1</mechanicalReduction>
            <hardwareInterface>hardware_interface/PositionJointInterface</hardwareInterface>
        </actuator>
    </transmission>
    <transmission name="Index_Finger_Joint2_trans">
        <type>transmission_interface/SimpleTransmission</type>
        <joint name="Index_Finger_Joint2">
            <hardwareInterface>hardware_interface/PositionJointInterface</hardwareInterface>
        </joint>
        <actuator name="Index_Finger_Joint2_motor">
            <mechanicalReduction>1</mechanicalReduction>
            <hardwareInterface>hardware_interface/PositionJointInterface</hardwareInterface>
        </actuator>
    </transmission>
    <transmission name="Big_Thump_Joint1_trans">
        <type>transmission_interface/SimpleTransmission</type>
        <joint name="Big_Thump_Joint1">
            <hardwareInterface>hardware_interface/PositionJointInterface</hardwareInterface>
        </joint>
        <actuator name="Big_Thump_Joint1_motor">
            <mechanicalReduction>1</mechanicalReduction>
            <hardwareInterface>hardware_interface/PositionJointInterface</hardwareInterface>
        </actuator>
    </transmission>
    <transmission name="Big_Thump_Joint2_trans">
        <type>transmission_interface/SimpleTransmission</type>
        <joint name="Big_Thump_Joint2">
            <hardwareInterface>hardware_interface/PositionJointInterface</hardwareInterface>
        </joint>
        <actuator name="Big_Thump_Joint2_motor">
            <mechanicalReduction>1</mechanicalReduction>
            <hardwareInterface>hardware_interface/PositionJointInterface</hardwareInterface>
        </actuator>
    </transmission>
    <transmission name="Big_Thump_Joint3_trans">
        <type>transmission_interface/SimpleTransmission</type>
        <joint name="Big_Thump_Joint3">
            <hardwareInterface>hardware_interface/PositionJointInterface</hardwareInterface>
        </joint>
        <actuator name="Big_Thump_Joint3_motor">
            <mechanicalReduction>1</mechanicalReduction>
            <hardwareInterface>hardware_interface/PositionJointInterface</hardwareInterface>
        </actuator>
    </transmission>
    <!-- ros_control plugin -->
    <gazebo>
        <plugin filename="libgazebo_ros_control.so" name="gazebo_ros_control">
            <robotNamespace>/</robotNamespace>
        </plugin>
    </gazebo>
    <joint name="inspire_hand_joint" type="fixed">
        <origin rpy="0.0 -1.534 0.0" xyz="0.0495 0.038 0.069" />
        <parent link="ft_sensor" />
        <child link="dummy" />
        <axis xyz="0.0 0.0 0.0" />
        <limit effort="0.0" lower="0.0" upper="0.0" velocity="0.0" />
    </joint>
    <link name="world" />
    <joint name="world_joint" type="fixed">
        <parent link="world" />
        <child link="xMateCR7_base" />
        <origin rpy="0.0 0.0 0.0" xyz="0.0 0.0 0.0" />
    </joint>
    <joint name="realsense_joint" type="fixed">
        <parent link="world" />
        <child link="base_link" />
        <origin rpy="0.0 1.57 0.0" xyz="0.75 0.0 1.2" />
    </joint>
    <link name="base_link" />
    <material name="camera_aluminum">
        <color rgba="0.5 0.5 0.5 1" />
    </material>
    <!-- camera body, with origin at bottom screw mount -->
    <joint name="camera_joint" type="fixed">
        <origin rpy="0 0 0" xyz="0 0 0" />
        <parent link="base_link" />
        <child link="camera_bottom_screw_frame" />
    </joint>
    <link name="camera_bottom_screw_frame" />
    <joint name="camera_link_joint" type="fixed">
        <origin rpy="0 0 0" xyz="0 0.0175 0.0125" />
        <parent link="camera_bottom_screw_frame" />
        <child link="camera_link" />
    </joint>
    <link name="camera_link">
        <visual>
            <origin rpy="1.5707963267948966 0 1.5707963267948966" xyz="0.0149 -0.0175 0" />
            <geometry>
                <!-- <box size="${d435_cam_width} ${d435_cam_height} ${d435_cam_depth}"/> -->
                <mesh filename="package://realsense2_description/meshes/d435.dae" />
                <!--<mesh filename="package://realsense2_description/meshes/d435/d435.dae" />-->
            </geometry>
            <material name="camera_aluminum" />
        </visual>
        <collision>
            <origin rpy="0 0 0" xyz="0 -0.0175 0" />
            <geometry>
                <box size="0.02505 0.09 0.025" />
            </geometry>
        </collision>
        <inertial>
            <!-- The following are not reliable values, and should not be used for modeling -->
            <mass value="0.564" />
            <origin xyz="0 0 0" rpy="0 0 0" />
            <inertia ixx="0.003881243" ixy="0.0" ixz="0.0" iyy="0.000498940" iyz="0.0" izz="0.003879257" />
        </inertial>
    </link>
    <!-- camera depth joints and links -->
    <joint name="camera_depth_joint" type="fixed">
        <origin rpy="0 0 0" xyz="0 0 0" />
        <parent link="camera_link" />
        <child link="camera_depth_frame" />
    </joint>
    <link name="camera_depth_frame" />
    <joint name="camera_depth_optical_joint" type="fixed">
        <origin rpy="-1.5707963267948966 0 -1.5707963267948966" xyz="0 0 0" />
        <parent link="camera_depth_frame" />
        <child link="camera_depth_optical_frame" />
    </joint>
    <link name="camera_depth_optical_frame" />
    <!-- camera left IR joints and links -->
    <joint name="camera_left_ir_joint" type="fixed">
        <origin rpy="0 0 0" xyz="0 0.0 0" />
        <parent link="camera_depth_frame" />
        <child link="camera_left_ir_frame" />
    </joint>
    <link name="camera_left_ir_frame" />
    <joint name="camera_left_ir_optical_joint" type="fixed">
        <origin rpy="-1.5707963267948966 0 -1.5707963267948966" xyz="0 0 0" />
        <parent link="camera_left_ir_frame" />
        <child link="camera_left_ir_optical_frame" />
    </joint>
    <link name="camera_left_ir_optical_frame" />
    <!-- camera right IR joints and links -->
    <joint name="camera_right_ir_joint" type="fixed">
        <origin rpy="0 0 0" xyz="0 -0.05 0" />
        <parent link="camera_depth_frame" />
        <child link="camera_right_ir_frame" />
    </joint>
    <link name="camera_right_ir_frame" />
    <joint name="camera_right_ir_optical_joint" type="fixed">
        <origin rpy="-1.5707963267948966 0 -1.5707963267948966" xyz="0 0 0" />
        <parent link="camera_right_ir_frame" />
        <child link="camera_right_ir_optical_frame" />
    </joint>
    <link name="camera_right_ir_optical_frame" />
    <!-- camera color joints and links -->
    <joint name="camera_color_joint" type="fixed">
        <origin rpy="0 0 0" xyz="0 0.015 0" />
        <parent link="camera_depth_frame" />
        <child link="camera_color_frame" />
    </joint>
    <link name="camera_color_frame" />
    <joint name="camera_color_optical_joint" type="fixed">
        <origin rpy="-1.5707963267948966 0 -1.5707963267948966" xyz="0 0 0" />
        <parent link="camera_color_frame" />
        <child link="camera_color_optical_frame" />
    </joint>
    <link name="camera_color_optical_frame" />
    <gazebo reference="camera_link">
        <self_collide>0</self_collide>
        <enable_wind>0</enable_wind>
        <kinematic>0</kinematic>
        <gravity>1</gravity>
        <!--<mu>1</mu>-->
        <mu2>1</mu2>
        <fdir1>0 0 0</fdir1>
        <!--<slip1>0</slip1>
      <slip2>0</slip2>-->
        <kp>1e+13</kp>
        <kd>1</kd>
        <!--<max_vel>0.01</max_vel>
      <min_depth>0</min_depth>-->
        <sensor name="cameracolor" type="camera">
            <camera name="camera">
                <!-- 改动！！应该具有相同的视野！！！！！！！！！！！！！！！！ -->
                <!-- <horizontal_fov>1.2112585008840648</horizontal_fov> -->
                <horizontal_fov>1.4870205226991688</horizontal_fov>
                <image>
                    <!-- <width>640</width>
                    <height>480</height> -->
                    <!-- 改动！！！！！！！！！！！！！！！！！！！！！！！！！！！！！！！！ -->
                    <width>1280</width>
                    <height>720</height>
                    <format>RGB_INT8</format>
                </image>
                <clip>
                    <near>0.1</near>
                    <far>100</far>
                </clip>
                <noise>
                    <type>gaussian</type>
                    <mean>0.0</mean>
                    <stddev>0.007</stddev>
                </noise>
            </camera>
            <always_on>1</always_on>
            <update_rate>30</update_rate>
            <visualize>1</visualize>
        </sensor>
        <sensor name="cameraired1" type="camera">
            <camera name="camera">
                <horizontal_fov>1.4870205226991688</horizontal_fov>
                <image>
                    <width>1280</width>
                    <height>720</height>
                    <format>L_INT8</format>
                </image>
                <clip>
                    <near>0.1</near>
                    <far>100</far>
                </clip>
                <noise>
                    <type>gaussian</type>
                    <mean>0.0</mean>
                    <stddev>0.05</stddev>
                </noise>
            </camera>
            <always_on>1</always_on>
            <update_rate>90</update_rate>
            <visualize>0</visualize>
        </sensor>
        <sensor name="cameraired2" type="camera">
            <camera name="camera">
                <horizontal_fov>1.4870205226991688</horizontal_fov>
                <image>
                    <width>1280</width>
                    <height>720</height>
                    <format>L_INT8</format>
                </image>
                <clip>
                    <near>0.1</near>
                    <far>100</far>
                </clip>
                <noise>
                    <type>gaussian</type>
                    <mean>0.0</mean>
                    <stddev>0.05</stddev>
                </noise>
            </camera>
            <always_on>1</always_on>
            <update_rate>90</update_rate>
            <visualize>0</visualize>
        </sensor>
        <sensor name="cameradepth" type="depth">
            <camera name="camera">
                <horizontal_fov>1.4870205226991688</horizontal_fov>
                <image>
                    <width>1280</width>
                    <height>720</height>
                </image>
                <clip>
                    <near>0.1</near>
                    <far>100</far>
                </clip>
                <noise>
                    <type>gaussian</type>
                    <mean>0.0</mean>
                    <stddev>0.100</stddev>
                </noise>
            </camera>
            <always_on>1</always_on>
            <update_rate>90</update_rate>
            <visualize>0</visualize>
        </sensor>
    </gazebo>
    <gazebo>
        <plugin filename="librealsense_gazebo_plugin.so" name="camera">
            <prefix>camera</prefix>
            <depthUpdateRate>30.0</depthUpdateRate>
            <colorUpdateRate>30.0</colorUpdateRate>
            <infraredUpdateRate>30.0</infraredUpdateRate>
            <!-- 注意修改此处，需要获得左眼的深度图 -->
            <depthTopicName>depth/image_raw_left</depthTopicName>
            <depthCameraInfoTopicName>depth/camera_info_left</depthCameraInfoTopicName>
            <!-- ！！！！！！！！！！！！！！！！！！！！！！！！！！！！！！！！！！！！！！！！！！！！！ -->
            <colorTopicName>color/image_raw</colorTopicName>
            <colorCameraInfoTopicName>color/camera_info</colorCameraInfoTopicName>
            <infrared1TopicName>infra1/image_raw</infrared1TopicName>
            <infrared1CameraInfoTopicName>infra1/camera_info</infrared1CameraInfoTopicName>
            <infrared2TopicName>infra2/image_raw</infrared2TopicName>
            <infrared2CameraInfoTopicName>infra2/camera_info</infrared2CameraInfoTopicName>
            <colorOpticalframeName>camera_color_optical_frame</colorOpticalframeName>
            <depthOpticalframeName>camera_depth_optical_frame</depthOpticalframeName>
            <infrared1OpticalframeName>camera_left_ir_optical_frame</infrared1OpticalframeName>
            <infrared2OpticalframeName>camera_right_ir_optical_frame</infrared2OpticalframeName>
            <rangeMinDepth>0.2</rangeMinDepth>
            <rangeMaxDepth>10.0</rangeMaxDepth>
            <pointCloud>True</pointCloud>
            <pointCloudTopicName>depth/color/points</pointCloudTopicName>
            <pointCloudCutoff>0.25</pointCloudCutoff>
            <pointCloudCutoffMax>9.0</pointCloudCutoffMax>
        </plugin>
    </gazebo>
    <transmission name="trans_Big_Thump_Joint4">
        <type>transmission_interface/SimpleTransmission</type>
        <joint name="Big_Thump_Joint4">
            <hardwareInterface>hardware_interface/PositionJointInterface</hardwareInterface>
        </joint>
        <actuator name="Big_Thump_Joint4_motor">
            <hardwareInterface>hardware_interface/PositionJointInterface</hardwareInterface>
            <mechanicalReduction>1</mechanicalReduction>
        </actuator>
    </transmission>
</robot>

